22-Oct-24 11:09:11 INFO [usecases.py] Processing recovery percentage and capacity utilization data...
22-Oct-24 11:36:31 INFO [usecases.py] Processing shift wise and zone wise water production data...
22-Oct-24 12:30:32 INFO [usecases.py] Processing shift wise and zone wise water production data...
22-Oct-24 12:47:47 INFO [usecases.py] Processing recovery percentage and capacity utilization data...
22-Oct-24 12:48:20 INFO [usecases.py] Processing plant_availability data...
22-Oct-24 12:48:32 INFO [usecases.py] Processing shift wise and zone wise water production data...
22-Oct-24 12:50:14 INFO [usecases.py] Processing shift wise and zone wise water production data...
22-Oct-24 12:51:38 INFO [usecases.py] Processing recovery percentage and capacity utilization data...
22-Oct-24 13:02:10 ERROR [usecases.py] Exception occurred: 'list' object has no attribute 'to_json'
Traceback (most recent call last):
  File "/Users/shilpa.av/Desktop/Bayesian_Ways/Amrut_Deployment/routers/usecases.py", line 21, in recovery_percentage_capacity_utilization
    processed_data.to_json(config.JSON_FILE_PATH['upload_file_path']+'recovery_percentage_capacity_utilization.json',orient='records')
    ^^^^^^^^^^^^^^^^^^^^^^
AttributeError: 'list' object has no attribute 'to_json'
22-Oct-24 13:03:58 ERROR [usecases.py] Exception occurred: 'list' object has no attribute 'to_json'
Traceback (most recent call last):
  File "/Users/shilpa.av/Desktop/Bayesian_Ways/Amrut_Deployment/routers/usecases.py", line 21, in recovery_percentage_capacity_utilization
    processed_data.to_json(config.JSON_FILE_PATH['upload_file_path']+'recovery_percentage_capacity_utilization.json',orient='records')
    ^^^^^^^^^^^^^^^^^^^^^^
AttributeError: 'list' object has no attribute 'to_json'
22-Oct-24 13:04:39 INFO [usecases.py] Processing recovery percentage and capacity utilization data...
22-Oct-24 13:05:26 ERROR [usecases.py] Exception occurred: 'list' object has no attribute 'to_json'
Traceback (most recent call last):
  File "/Users/shilpa.av/Desktop/Bayesian_Ways/Amrut_Deployment/routers/usecases.py", line 42, in plant_availability
    processed_data.to_json(config.JSON_FILE_PATH['upload_file_path']+'plant_availability.json',orient='records')
    ^^^^^^^^^^^^^^^^^^^^^^
AttributeError: 'list' object has no attribute 'to_json'
22-Oct-24 13:06:38 ERROR [usecases.py] Exception occurred: 'list' object has no attribute 'to_json'
Traceback (most recent call last):
  File "/Users/shilpa.av/Desktop/Bayesian_Ways/Amrut_Deployment/routers/usecases.py", line 18, in recovery_percentage_capacity_utilization
    processed_data = data_processor.recovery_percentage_capacity_utilization_finder()
                     ^^^^^^^^^^^^^^^^^^^^^^^^^^^^^^^^^^^^^^^^^^^^^^^^^^^^^^^^^^^^^^^^
  File "/Users/shilpa.av/Desktop/Bayesian_Ways/Amrut_Deployment/visualization_model.py", line 30, in recovery_percentage_capacity_utilization_finder
    data_day.to_json(config.JSON_FILE_PATH['upload_file_path']+'plant_availability.json',orient='records')
    ^^^^^^^^^^^^^^^^
AttributeError: 'list' object has no attribute 'to_json'
22-Oct-24 13:09:25 INFO [usecases.py] Processing recovery percentage and capacity utilization data...
22-Oct-24 13:10:03 INFO [usecases.py] Processing recovery percentage and capacity utilization data...
22-Oct-24 13:11:29 INFO [usecases.py] Processing plant_availability data...
22-Oct-24 13:12:34 INFO [usecases.py] Processing recovery percentage and capacity utilization data...
22-Oct-24 13:35:46 ERROR [usecases.py] Exception occurred: 'Standardized_Date'
Traceback (most recent call last):
  File "/Users/shilpa.av/Desktop/Bayesian_Ways/Amrut_Deployment/myenv/lib/python3.12/site-packages/pandas/core/indexes/base.py", line 3805, in get_loc
    return self._engine.get_loc(casted_key)
           ^^^^^^^^^^^^^^^^^^^^^^^^^^^^^^^^
  File "index.pyx", line 167, in pandas._libs.index.IndexEngine.get_loc
  File "index.pyx", line 196, in pandas._libs.index.IndexEngine.get_loc
  File "pandas/_libs/hashtable_class_helper.pxi", line 7081, in pandas._libs.hashtable.PyObjectHashTable.get_item
  File "pandas/_libs/hashtable_class_helper.pxi", line 7089, in pandas._libs.hashtable.PyObjectHashTable.get_item
KeyError: 'Standardized_Date'

The above exception was the direct cause of the following exception:

Traceback (most recent call last):
  File "/Users/shilpa.av/Desktop/Bayesian_Ways/Amrut_Deployment/routers/usecases.py", line 73, in shift_and_zone_wise_water_production
    processed_data = data_processor.shift_and_zone_water_production_finder()
                     ^^^^^^^^^^^^^^^^^^^^^^^^^^^^^^^^^^^^^^^^^^^^^^^^^^^^^^^
  File "/Users/shilpa.av/Desktop/Bayesian_Ways/Amrut_Deployment/visualization_model.py", line 70, in shift_and_zone_water_production_finder
    data=data[(data['Standardized_Date']>='2024-06-01') & (data['Standardized_Date']<='2024-08-28')]
               ~~~~^^^^^^^^^^^^^^^^^^^^^
  File "/Users/shilpa.av/Desktop/Bayesian_Ways/Amrut_Deployment/myenv/lib/python3.12/site-packages/pandas/core/frame.py", line 4102, in __getitem__
    indexer = self.columns.get_loc(key)
              ^^^^^^^^^^^^^^^^^^^^^^^^^
  File "/Users/shilpa.av/Desktop/Bayesian_Ways/Amrut_Deployment/myenv/lib/python3.12/site-packages/pandas/core/indexes/base.py", line 3812, in get_loc
    raise KeyError(key) from err
KeyError: 'Standardized_Date'
22-Oct-24 13:36:31 INFO [usecases.py] Processing shift wise and zone wise water production data...
22-Oct-24 13:56:54 ERROR [usecases.py] Exception occurred: 'Standardized_Date'
Traceback (most recent call last):
  File "/Users/shilpa.av/Desktop/Bayesian_Ways/Amrut_Deployment/myenv/lib/python3.12/site-packages/pandas/core/indexes/base.py", line 3805, in get_loc
    return self._engine.get_loc(casted_key)
           ^^^^^^^^^^^^^^^^^^^^^^^^^^^^^^^^
  File "index.pyx", line 167, in pandas._libs.index.IndexEngine.get_loc
  File "index.pyx", line 196, in pandas._libs.index.IndexEngine.get_loc
  File "pandas/_libs/hashtable_class_helper.pxi", line 7081, in pandas._libs.hashtable.PyObjectHashTable.get_item
  File "pandas/_libs/hashtable_class_helper.pxi", line 7089, in pandas._libs.hashtable.PyObjectHashTable.get_item
KeyError: 'Standardized_Date'

The above exception was the direct cause of the following exception:

Traceback (most recent call last):
  File "/Users/shilpa.av/Desktop/Bayesian_Ways/Amrut_Deployment/routers/usecases.py", line 91, in ebill_analysis
    processed_data = data_processor.ebill_new_columns_adder()
                     ^^^^^^^^^^^^^^^^^^^^^^^^^^^^^^^^^^^^^^^^
  File "/Users/shilpa.av/Desktop/Bayesian_Ways/Amrut_Deployment/visualization_model.py", line 80, in ebill_new_columns_adder
    data['Standardized_Date'] = pd.to_datetime(data['Standardized_Date'])
                                               ~~~~^^^^^^^^^^^^^^^^^^^^^
  File "/Users/shilpa.av/Desktop/Bayesian_Ways/Amrut_Deployment/myenv/lib/python3.12/site-packages/pandas/core/frame.py", line 4102, in __getitem__
    indexer = self.columns.get_loc(key)
              ^^^^^^^^^^^^^^^^^^^^^^^^^
  File "/Users/shilpa.av/Desktop/Bayesian_Ways/Amrut_Deployment/myenv/lib/python3.12/site-packages/pandas/core/indexes/base.py", line 3812, in get_loc
    raise KeyError(key) from err
KeyError: 'Standardized_Date'
22-Oct-24 13:57:59 ERROR [usecases.py] Exception occurred: "None of ['Standardized_Date'] are in the columns"
Traceback (most recent call last):
  File "/Users/shilpa.av/Desktop/Bayesian_Ways/Amrut_Deployment/routers/usecases.py", line 91, in ebill_analysis
    processed_data = data_processor.ebill_new_columns_adder()
                     ^^^^^^^^^^^^^^^^^^^^^^^^^^^^^^^^^^^^^^^^
  File "/Users/shilpa.av/Desktop/Bayesian_Ways/Amrut_Deployment/visualization_model.py", line 81, in ebill_new_columns_adder
    data = data.set_index('Standardized_Date')
           ^^^^^^^^^^^^^^^^^^^^^^^^^^^^^^^^^^^
  File "/Users/shilpa.av/Desktop/Bayesian_Ways/Amrut_Deployment/myenv/lib/python3.12/site-packages/pandas/core/frame.py", line 6122, in set_index
    raise KeyError(f"None of {missing} are in the columns")
KeyError: "None of ['Standardized_Date'] are in the columns"
22-Oct-24 13:58:52 ERROR [usecases.py] Exception occurred: 'Zone'
Traceback (most recent call last):
  File "/Users/shilpa.av/Desktop/Bayesian_Ways/Amrut_Deployment/routers/usecases.py", line 91, in ebill_analysis
    processed_data = data_processor.ebill_new_columns_adder()
                     ^^^^^^^^^^^^^^^^^^^^^^^^^^^^^^^^^^^^^^^^
  File "/Users/shilpa.av/Desktop/Bayesian_Ways/Amrut_Deployment/visualization_model.py", line 82, in ebill_new_columns_adder
    data_month_start = data.groupby(['Zone']).resample('M').agg({'RAW WATER FLOW IN ML':'sum',
                       ^^^^^^^^^^^^^^^^^^^^^^
  File "/Users/shilpa.av/Desktop/Bayesian_Ways/Amrut_Deployment/myenv/lib/python3.12/site-packages/pandas/core/frame.py", line 9183, in groupby
    return DataFrameGroupBy(
           ^^^^^^^^^^^^^^^^^
  File "/Users/shilpa.av/Desktop/Bayesian_Ways/Amrut_Deployment/myenv/lib/python3.12/site-packages/pandas/core/groupby/groupby.py", line 1329, in __init__
    grouper, exclusions, obj = get_grouper(
                               ^^^^^^^^^^^^
  File "/Users/shilpa.av/Desktop/Bayesian_Ways/Amrut_Deployment/myenv/lib/python3.12/site-packages/pandas/core/groupby/grouper.py", line 1043, in get_grouper
    raise KeyError(gpr)
KeyError: 'Zone'
22-Oct-24 13:59:57 ERROR [usecases.py] Exception occurred: 'Hour'
Traceback (most recent call last):
  File "/Users/shilpa.av/Desktop/Bayesian_Ways/Amrut_Deployment/myenv/lib/python3.12/site-packages/pandas/core/indexes/base.py", line 3805, in get_loc
    return self._engine.get_loc(casted_key)
           ^^^^^^^^^^^^^^^^^^^^^^^^^^^^^^^^
  File "index.pyx", line 167, in pandas._libs.index.IndexEngine.get_loc
  File "index.pyx", line 196, in pandas._libs.index.IndexEngine.get_loc
  File "pandas/_libs/hashtable_class_helper.pxi", line 7081, in pandas._libs.hashtable.PyObjectHashTable.get_item
  File "pandas/_libs/hashtable_class_helper.pxi", line 7089, in pandas._libs.hashtable.PyObjectHashTable.get_item
KeyError: 'Hour'

The above exception was the direct cause of the following exception:

Traceback (most recent call last):
  File "/Users/shilpa.av/Desktop/Bayesian_Ways/Amrut_Deployment/routers/usecases.py", line 91, in ebill_analysis
    processed_data = data_processor.ebill_new_columns_adder()
                     ^^^^^^^^^^^^^^^^^^^^^^^^^^^^^^^^^^^^^^^^
  File "/Users/shilpa.av/Desktop/Bayesian_Ways/Amrut_Deployment/visualization_model.py", line 82, in ebill_new_columns_adder
    data['Zone'] = data['Hour'].apply(self.assign_zone)
                   ~~~~^^^^^^^^
  File "/Users/shilpa.av/Desktop/Bayesian_Ways/Amrut_Deployment/myenv/lib/python3.12/site-packages/pandas/core/frame.py", line 4102, in __getitem__
    indexer = self.columns.get_loc(key)
              ^^^^^^^^^^^^^^^^^^^^^^^^^
  File "/Users/shilpa.av/Desktop/Bayesian_Ways/Amrut_Deployment/myenv/lib/python3.12/site-packages/pandas/core/indexes/base.py", line 3812, in get_loc
    raise KeyError(key) from err
KeyError: 'Hour'
22-Oct-24 14:00:21 ERROR [usecases.py] Exception occurred: 'unique' is not a valid function for 'DatetimeIndexResamplerGroupby' object
Traceback (most recent call last):
  File "/Users/shilpa.av/Desktop/Bayesian_Ways/Amrut_Deployment/routers/usecases.py", line 91, in ebill_analysis
    processed_data = data_processor.ebill_new_columns_adder()
                     ^^^^^^^^^^^^^^^^^^^^^^^^^^^^^^^^^^^^^^^^
  File "/Users/shilpa.av/Desktop/Bayesian_Ways/Amrut_Deployment/visualization_model.py", line 84, in ebill_new_columns_adder
    data_month_start = data.groupby(['Zone']).resample('M').agg({'RAW WATER FLOW IN ML':'sum',
                       ^^^^^^^^^^^^^^^^^^^^^^^^^^^^^^^^^^^^^^^^^^^^^^^^^^^^^^^^^^^^^^^^^^^^^^^
  File "/Users/shilpa.av/Desktop/Bayesian_Ways/Amrut_Deployment/myenv/lib/python3.12/site-packages/pandas/core/resample.py", line 352, in aggregate
    result = ResamplerWindowApply(self, func, args=args, kwargs=kwargs).agg()
             ^^^^^^^^^^^^^^^^^^^^^^^^^^^^^^^^^^^^^^^^^^^^^^^^^^^^^^^^^^^^^^^^
  File "/Users/shilpa.av/Desktop/Bayesian_Ways/Amrut_Deployment/myenv/lib/python3.12/site-packages/pandas/core/apply.py", line 190, in agg
    return self.agg_dict_like()
           ^^^^^^^^^^^^^^^^^^^^
  File "/Users/shilpa.av/Desktop/Bayesian_Ways/Amrut_Deployment/myenv/lib/python3.12/site-packages/pandas/core/apply.py", line 423, in agg_dict_like
    return self.agg_or_apply_dict_like(op_name="agg")
           ^^^^^^^^^^^^^^^^^^^^^^^^^^^^^^^^^^^^^^^^^^
  File "/Users/shilpa.av/Desktop/Bayesian_Ways/Amrut_Deployment/myenv/lib/python3.12/site-packages/pandas/core/apply.py", line 1608, in agg_or_apply_dict_like
    result_index, result_data = self.compute_dict_like(
                                ^^^^^^^^^^^^^^^^^^^^^^^
  File "/Users/shilpa.av/Desktop/Bayesian_Ways/Amrut_Deployment/myenv/lib/python3.12/site-packages/pandas/core/apply.py", line 497, in compute_dict_like
    getattr(obj._gotitem(key, ndim=1), op_name)(how, **kwargs)
  File "/Users/shilpa.av/Desktop/Bayesian_Ways/Amrut_Deployment/myenv/lib/python3.12/site-packages/pandas/core/resample.py", line 352, in aggregate
    result = ResamplerWindowApply(self, func, args=args, kwargs=kwargs).agg()
             ^^^^^^^^^^^^^^^^^^^^^^^^^^^^^^^^^^^^^^^^^^^^^^^^^^^^^^^^^^^^^^^^
  File "/Users/shilpa.av/Desktop/Bayesian_Ways/Amrut_Deployment/myenv/lib/python3.12/site-packages/pandas/core/apply.py", line 187, in agg
    return self.apply_str()
           ^^^^^^^^^^^^^^^^
  File "/Users/shilpa.av/Desktop/Bayesian_Ways/Amrut_Deployment/myenv/lib/python3.12/site-packages/pandas/core/apply.py", line 603, in apply_str
    return self._apply_str(obj, func, *self.args, **self.kwargs)
           ^^^^^^^^^^^^^^^^^^^^^^^^^^^^^^^^^^^^^^^^^^^^^^^^^^^^^
  File "/Users/shilpa.av/Desktop/Bayesian_Ways/Amrut_Deployment/myenv/lib/python3.12/site-packages/pandas/core/apply.py", line 706, in _apply_str
    raise AttributeError(msg)
AttributeError: 'unique' is not a valid function for 'DatetimeIndexResamplerGroupby' object
22-Oct-24 14:01:23 ERROR [usecases.py] Exception occurred: 'unique' is not a valid function for 'DatetimeIndexResamplerGroupby' object
Traceback (most recent call last):
  File "/Users/shilpa.av/Desktop/Bayesian_Ways/Amrut_Deployment/routers/usecases.py", line 91, in ebill_analysis
    processed_data = data_processor.ebill_new_columns_adder()
                     ^^^^^^^^^^^^^^^^^^^^^^^^^^^^^^^^^^^^^^^^
  File "/Users/shilpa.av/Desktop/Bayesian_Ways/Amrut_Deployment/visualization_model.py", line 84, in ebill_new_columns_adder
    data_month_start = data.groupby(['Zone']).resample('M').agg({'RAW WATER FLOW IN ML':'sum',
                       ^^^^^^^^^^^^^^^^^^^^^^^^^^^^^^^^^^^^^^^^^^^^^^^^^^^^^^^^^^^^^^^^^^^^^^^
  File "/Users/shilpa.av/Desktop/Bayesian_Ways/Amrut_Deployment/myenv/lib/python3.12/site-packages/pandas/core/resample.py", line 352, in aggregate
    result = ResamplerWindowApply(self, func, args=args, kwargs=kwargs).agg()
             ^^^^^^^^^^^^^^^^^^^^^^^^^^^^^^^^^^^^^^^^^^^^^^^^^^^^^^^^^^^^^^^^
  File "/Users/shilpa.av/Desktop/Bayesian_Ways/Amrut_Deployment/myenv/lib/python3.12/site-packages/pandas/core/apply.py", line 190, in agg
    return self.agg_dict_like()
           ^^^^^^^^^^^^^^^^^^^^
  File "/Users/shilpa.av/Desktop/Bayesian_Ways/Amrut_Deployment/myenv/lib/python3.12/site-packages/pandas/core/apply.py", line 423, in agg_dict_like
    return self.agg_or_apply_dict_like(op_name="agg")
           ^^^^^^^^^^^^^^^^^^^^^^^^^^^^^^^^^^^^^^^^^^
  File "/Users/shilpa.av/Desktop/Bayesian_Ways/Amrut_Deployment/myenv/lib/python3.12/site-packages/pandas/core/apply.py", line 1608, in agg_or_apply_dict_like
    result_index, result_data = self.compute_dict_like(
                                ^^^^^^^^^^^^^^^^^^^^^^^
  File "/Users/shilpa.av/Desktop/Bayesian_Ways/Amrut_Deployment/myenv/lib/python3.12/site-packages/pandas/core/apply.py", line 497, in compute_dict_like
    getattr(obj._gotitem(key, ndim=1), op_name)(how, **kwargs)
  File "/Users/shilpa.av/Desktop/Bayesian_Ways/Amrut_Deployment/myenv/lib/python3.12/site-packages/pandas/core/resample.py", line 352, in aggregate
    result = ResamplerWindowApply(self, func, args=args, kwargs=kwargs).agg()
             ^^^^^^^^^^^^^^^^^^^^^^^^^^^^^^^^^^^^^^^^^^^^^^^^^^^^^^^^^^^^^^^^
  File "/Users/shilpa.av/Desktop/Bayesian_Ways/Amrut_Deployment/myenv/lib/python3.12/site-packages/pandas/core/apply.py", line 187, in agg
    return self.apply_str()
           ^^^^^^^^^^^^^^^^
  File "/Users/shilpa.av/Desktop/Bayesian_Ways/Amrut_Deployment/myenv/lib/python3.12/site-packages/pandas/core/apply.py", line 603, in apply_str
    return self._apply_str(obj, func, *self.args, **self.kwargs)
           ^^^^^^^^^^^^^^^^^^^^^^^^^^^^^^^^^^^^^^^^^^^^^^^^^^^^^
  File "/Users/shilpa.av/Desktop/Bayesian_Ways/Amrut_Deployment/myenv/lib/python3.12/site-packages/pandas/core/apply.py", line 706, in _apply_str
    raise AttributeError(msg)
AttributeError: 'unique' is not a valid function for 'DatetimeIndexResamplerGroupby' object
22-Oct-24 14:02:25 ERROR [usecases.py] Exception occurred: Missing optional dependency 'openpyxl'.  Use pip or conda to install openpyxl.
Traceback (most recent call last):
  File "/Users/shilpa.av/Desktop/Bayesian_Ways/Amrut_Deployment/myenv/lib/python3.12/site-packages/pandas/compat/_optional.py", line 135, in import_optional_dependency
    module = importlib.import_module(name)
             ^^^^^^^^^^^^^^^^^^^^^^^^^^^^^
  File "/usr/local/Cellar/python@3.12/3.12.4/Frameworks/Python.framework/Versions/3.12/lib/python3.12/importlib/__init__.py", line 90, in import_module
    return _bootstrap._gcd_import(name[level:], package, level)
           ^^^^^^^^^^^^^^^^^^^^^^^^^^^^^^^^^^^^^^^^^^^^^^^^^^^^
  File "<frozen importlib._bootstrap>", line 1387, in _gcd_import
  File "<frozen importlib._bootstrap>", line 1360, in _find_and_load
  File "<frozen importlib._bootstrap>", line 1324, in _find_and_load_unlocked
ModuleNotFoundError: No module named 'openpyxl'

During handling of the above exception, another exception occurred:

Traceback (most recent call last):
  File "/Users/shilpa.av/Desktop/Bayesian_Ways/Amrut_Deployment/routers/usecases.py", line 91, in ebill_analysis
    processed_data = data_processor.ebill_new_columns_adder()
                     ^^^^^^^^^^^^^^^^^^^^^^^^^^^^^^^^^^^^^^^^
  File "/Users/shilpa.av/Desktop/Bayesian_Ways/Amrut_Deployment/visualization_model.py", line 101, in ebill_new_columns_adder
    df=pd.read_excel(config.CSV_FILE_PATH['upload_file_path']+config.DATA_FILE_NAMES['visualization_data_csv_file_name2'],index_col='Standardized_Date',parse_dates=True)
       ^^^^^^^^^^^^^^^^^^^^^^^^^^^^^^^^^^^^^^^^^^^^^^^^^^^^^^^^^^^^^^^^^^^^^^^^^^^^^^^^^^^^^^^^^^^^^^^^^^^^^^^^^^^^^^^^^^^^^^^^^^^^^^^^^^^^^^^^^^^^^^^^^^^^^^^^^^^^^^^^^^
  File "/Users/shilpa.av/Desktop/Bayesian_Ways/Amrut_Deployment/myenv/lib/python3.12/site-packages/pandas/io/excel/_base.py", line 495, in read_excel
    io = ExcelFile(
         ^^^^^^^^^^
  File "/Users/shilpa.av/Desktop/Bayesian_Ways/Amrut_Deployment/myenv/lib/python3.12/site-packages/pandas/io/excel/_base.py", line 1567, in __init__
    self._reader = self._engines[engine](
                   ^^^^^^^^^^^^^^^^^^^^^^
  File "/Users/shilpa.av/Desktop/Bayesian_Ways/Amrut_Deployment/myenv/lib/python3.12/site-packages/pandas/io/excel/_openpyxl.py", line 552, in __init__
    import_optional_dependency("openpyxl")
  File "/Users/shilpa.av/Desktop/Bayesian_Ways/Amrut_Deployment/myenv/lib/python3.12/site-packages/pandas/compat/_optional.py", line 138, in import_optional_dependency
    raise ImportError(msg)
ImportError: Missing optional dependency 'openpyxl'.  Use pip or conda to install openpyxl.
22-Oct-24 14:05:28 INFO [usecases.py] Processing ebill data...
22-Oct-24 14:07:15 INFO [usecases.py] Processing ebill data...
22-Oct-24 14:10:39 ERROR [usecases.py] Exception occurred: 'list' object has no attribute 'to_json'
Traceback (most recent call last):
  File "/Users/shilpa.av/Desktop/Bayesian_Ways/Amrut_Deployment/routers/usecases.py", line 95, in ebill_analysis
    processed_data.to_json(config.JSON_FILE_PATH['upload_file_path']+'ebill_analysis.json',orient='records')
    ^^^^^^^^^^^^^^^^^^^^^^
AttributeError: 'list' object has no attribute 'to_json'
22-Oct-24 14:11:13 ERROR [usecases.py] Exception occurred: 'list' object has no attribute 'to_json'
Traceback (most recent call last):
  File "/Users/shilpa.av/Desktop/Bayesian_Ways/Amrut_Deployment/routers/usecases.py", line 95, in ebill_analysis
    processed_data.to_json(config.JSON_FILE_PATH['upload_file_path']+'ebill_analysis.json',orient='records')
    ^^^^^^^^^^^^^^^^^^^^^^
AttributeError: 'list' object has no attribute 'to_json'
22-Oct-24 14:11:32 INFO [usecases.py] Processing ebill data...
22-Oct-24 14:12:04 INFO [usecases.py] Processing ebill data...
22-Oct-24 14:12:18 ERROR [usecases.py] Exception occurred: 'list' object has no attribute 'to_dict'
Traceback (most recent call last):
  File "/Users/shilpa.av/Desktop/Bayesian_Ways/Amrut_Deployment/routers/usecases.py", line 97, in ebill_analysis
    processed_data = processed_data.to_dict('records')
                     ^^^^^^^^^^^^^^^^^^^^^^
AttributeError: 'list' object has no attribute 'to_dict'
22-Oct-24 14:12:48 INFO [usecases.py] Processing ebill data...
22-Oct-24 14:13:15 INFO [usecases.py] Processing ebill data...
22-Oct-24 14:13:37 INFO [usecases.py] Processing ebill data...
22-Oct-24 14:14:50 INFO [usecases.py] Processing ebill data...
22-Oct-24 14:15:25 INFO [usecases.py] Processing ebill data...
22-Oct-24 14:16:28 INFO [usecases.py] Processing ebill data...
22-Oct-24 14:17:16 INFO [usecases.py] Processing ebill data...
22-Oct-24 14:17:56 INFO [usecases.py] Processing ebill data...
22-Oct-24 14:18:44 ERROR [usecases.py] Exception occurred: 'list' object has no attribute 'to_dict'
Traceback (most recent call last):
  File "/Users/shilpa.av/Desktop/Bayesian_Ways/Amrut_Deployment/routers/usecases.py", line 97, in ebill_analysis
    processed_data = processed_data.to_dict('records')
                     ^^^^^^^^^^^^^^^^^^^^^^
AttributeError: 'list' object has no attribute 'to_dict'
22-Oct-24 14:19:37 INFO [usecases.py] Processing ebill data...
22-Oct-24 14:20:36 INFO [usecases.py] Processing ebill data...
22-Oct-24 14:22:48 INFO [usecases.py] Processing ebill data...
22-Oct-24 14:24:28 INFO [usecases.py] Processing ebill data...
22-Oct-24 14:27:40 INFO [usecases.py] Processed Data (first 5 rows):   Standardized_Date RAW_WATER_FLOW_IN_ML_Z1 RAW_WATER_FLOW_IN_ML_Z2  ... specific_energy_consumption charge_per_unit unit_cost
0        2021-12-01              1096.05734               328.28767  ...                         NaN             NaN       NaN
1        2022-01-01              1057.10504               298.59417  ...                         NaN             NaN       NaN
2        2022-02-01               967.26714                302.6117  ...                         NaN             NaN       NaN
3        2022-03-01              1185.29384               355.02836  ...                         NaN             NaN       NaN
4        2022-04-01             1067.816403               303.46002  ...                         NaN             NaN       NaN

[5 rows x 51 columns]
22-Oct-24 14:27:40 INFO [usecases.py] Ebill data successfully processed and saved as JSON.
22-Oct-24 14:28:43 INFO [usecases.py] Processing plant_availability data...
22-Oct-24 14:29:18 INFO [usecases.py] Processing plant_availability data...
22-Oct-24 14:29:25 INFO [usecases.py] Processing ebill data...
22-Oct-24 14:30:08 INFO [usecases.py] Processing ebill data...
22-Oct-24 14:30:38 INFO [usecases.py] Processing ebill data...
22-Oct-24 14:31:38 ERROR [usecases.py] Exception occurred: 'list' object has no attribute 'to_json'
Traceback (most recent call last):
  File "/Users/shilpa.av/Desktop/Bayesian_Ways/Amrut_Deployment/routers/usecases.py", line 95, in ebill_analysis
    processed_data.to_json(config.JSON_FILE_PATH['upload_file_path']+'ebill_analysis.json',orient='records')
    ^^^^^^^^^^^^^^^^^^^^^^
AttributeError: 'list' object has no attribute 'to_json'
22-Oct-24 14:32:12 ERROR [usecases.py] Exception occurred: 'list' object has no attribute 'to_dict'
Traceback (most recent call last):
  File "/Users/shilpa.av/Desktop/Bayesian_Ways/Amrut_Deployment/routers/usecases.py", line 97, in ebill_analysis
    processed_data = processed_data.to_dict('records')
                     ^^^^^^^^^^^^^^^^^^^^^^
AttributeError: 'list' object has no attribute 'to_dict'
22-Oct-24 14:32:30 INFO [usecases.py] Processing ebill data...
22-Oct-24 14:33:41 INFO [usecases.py] Processing ebill data...
22-Oct-24 14:35:33 INFO [usecases.py] Processing ebill data...
22-Oct-24 14:38:07 ERROR [usecases.py] Exception occurred: "['no of pumps_z1', 'no of pumps_z2', 'no of pumps_z3'] not in index"
Traceback (most recent call last):
  File "/Users/shilpa.av/Desktop/Bayesian_Ways/Amrut_Deployment/routers/usecases.py", line 91, in ebill_analysis
    processed_data = data_processor.ebill_new_columns_adder()
                     ^^^^^^^^^^^^^^^^^^^^^^^^^^^^^^^^^^^^^^^^
  File "/Users/shilpa.av/Desktop/Bayesian_Ways/Amrut_Deployment/visualization_model.py", line 128, in ebill_new_columns_adder
    data_month_ebill=data_month_ebill[['Demand factor', 'Utilization factor', 'Load Factor', 'no of pumps_z1',
                     ^^^^^^^^^^^^^^^^^^^^^^^^^^^^^^^^^^^^^^^^^^^^^^^^^^^^^^^^^^^^^^^^^^^^^^^^^^^^^^^^^^^^^^^^^
  File "/Users/shilpa.av/Desktop/Bayesian_Ways/Amrut_Deployment/myenv/lib/python3.12/site-packages/pandas/core/frame.py", line 4108, in __getitem__
    indexer = self.columns._get_indexer_strict(key, "columns")[1]
              ^^^^^^^^^^^^^^^^^^^^^^^^^^^^^^^^^^^^^^^^^^^^^^^^
  File "/Users/shilpa.av/Desktop/Bayesian_Ways/Amrut_Deployment/myenv/lib/python3.12/site-packages/pandas/core/indexes/base.py", line 6200, in _get_indexer_strict
    self._raise_if_missing(keyarr, indexer, axis_name)
  File "/Users/shilpa.av/Desktop/Bayesian_Ways/Amrut_Deployment/myenv/lib/python3.12/site-packages/pandas/core/indexes/base.py", line 6252, in _raise_if_missing
    raise KeyError(f"{not_found} not in index")
KeyError: "['no of pumps_z1', 'no of pumps_z2', 'no of pumps_z3'] not in index"
22-Oct-24 14:38:43 INFO [usecases.py] Processing ebill data...
22-Oct-24 14:40:56 INFO [usecases.py] Processing ebill data...
22-Oct-24 14:42:35 INFO [usecases.py] Processing ebill data...
22-Oct-24 14:50:08 INFO [usecases.py] Processing ebill data...
22-Oct-24 14:50:57 INFO [usecases.py] Processing ebill data...
22-Oct-24 14:51:36 INFO [usecases.py] Processing ebill data...
22-Oct-24 14:54:43 INFO [usecases.py] Processing ebill data...
22-Oct-24 14:55:45 INFO [usecases.py] Processing ebill data...
22-Oct-24 14:57:15 INFO [usecases.py] Processing ebill data...
22-Oct-24 14:58:43 INFO [usecases.py] Processing ebill data...
22-Oct-24 14:59:27 INFO [usecases.py] Processing ebill data...
22-Oct-24 15:34:28 INFO [usecases.py] Processing ebill data...
22-Oct-24 15:36:23 ERROR [usecases.py] Exception occurred: 'remarks category'
Traceback (most recent call last):
  File "/Users/shilpa.av/Desktop/Bayesian_Ways/Amrut_Deployment/myenv/lib/python3.12/site-packages/pandas/core/indexes/base.py", line 3805, in get_loc
    return self._engine.get_loc(casted_key)
           ^^^^^^^^^^^^^^^^^^^^^^^^^^^^^^^^
  File "index.pyx", line 167, in pandas._libs.index.IndexEngine.get_loc
  File "index.pyx", line 196, in pandas._libs.index.IndexEngine.get_loc
  File "pandas/_libs/hashtable_class_helper.pxi", line 7081, in pandas._libs.hashtable.PyObjectHashTable.get_item
  File "pandas/_libs/hashtable_class_helper.pxi", line 7089, in pandas._libs.hashtable.PyObjectHashTable.get_item
KeyError: 'remarks category'

The above exception was the direct cause of the following exception:

Traceback (most recent call last):
  File "/Users/shilpa.av/Desktop/Bayesian_Ways/Amrut_Deployment/routers/usecases.py", line 91, in ebill_analysis
    processed_data = data_processor.ebill_new_columns_adder()
                     ^^^^^^^^^^^^^^^^^^^^^^^^^^^^^^^^^^^^^^^^
  File "/Users/shilpa.av/Desktop/Bayesian_Ways/Amrut_Deployment/visualization_model.py", line 128, in ebill_new_columns_adder
    data_month_ebill['remarks category'] = data_month_ebill['remarks category'].apply(lambda x: list(x))
                                           ~~~~~~~~~~~~~~~~^^^^^^^^^^^^^^^^^^^^
  File "/Users/shilpa.av/Desktop/Bayesian_Ways/Amrut_Deployment/myenv/lib/python3.12/site-packages/pandas/core/frame.py", line 4102, in __getitem__
    indexer = self.columns.get_loc(key)
              ^^^^^^^^^^^^^^^^^^^^^^^^^
  File "/Users/shilpa.av/Desktop/Bayesian_Ways/Amrut_Deployment/myenv/lib/python3.12/site-packages/pandas/core/indexes/base.py", line 3812, in get_loc
    raise KeyError(key) from err
KeyError: 'remarks category'
22-Oct-24 15:37:35 INFO [usecases.py] Processing ebill data...
22-Oct-24 15:46:16 INFO [usecases.py] Processing ebill data...
22-Oct-24 15:47:14 INFO [usecases.py] Processing ebill data...
22-Oct-24 15:48:12 INFO [usecases.py] Processing ebill data...
22-Oct-24 15:49:45 INFO [usecases.py] Processing ebill data...
22-Oct-24 16:02:01 INFO [usecases.py] Processing ebill data...
22-Oct-24 16:02:38 INFO [usecases.py] Processing ebill data...
22-Oct-24 16:15:44 INFO [usecases.py] Processing ebill data...
